I1128 14:54:46.545465   38804 desired_state_of_world_populator.go:318] Added volume "volume1" (volSpec="local-pv4txvc") for pod "7dfc5864-f2da-11e8-ac39-000c299a5e15" to desired state.
I1128 14:54:46.586850   38804 reconciler.go:207] operationExecutor.VerifyControllerAttachedVolume started for volume "local-pv4txvc" (UniqueName: "kubernetes.io/local-volume/7dfc5864-f2da-11e8-ac39-000c299a5e15-local-pv4txvc") pod "security-context-7dfc4589-f2da-11e8-a0e3-000c299a5e15" (UID: "7dfc5864-f2da-11e8-ac39-000c299a5e15") 
I1128 14:54:46.687628   38804 reconciler.go:237] Starting operationExecutor.MountVolume for volume "local-pv4txvc" (UniqueName: "kubernetes.io/local-volume/7dfc5864-f2da-11e8-ac39-000c299a5e15-local-pv4txvc") pod "security-context-7dfc4589-f2da-11e8-a0e3-000c299a5e15" (UID: "7dfc5864-f2da-11e8-ac39-000c299a5e15") 
I1128 14:54:46.687719   38804 reconciler.go:252] operationExecutor.MountVolume started for volume "local-pv4txvc" (UniqueName: "kubernetes.io/local-volume/7dfc5864-f2da-11e8-ac39-000c299a5e15-local-pv4txvc") pod "security-context-7dfc4589-f2da-11e8-a0e3-000c299a5e15" (UID: "7dfc5864-f2da-11e8-ac39-000c299a5e15") 

# cofyc: kubelet mount device for pod 1
I1128 14:54:46.687810   38804 local.go:260] local: mounting device /dev/loop3 to /var/lib/kubelet/plugins/kubernetes.io/local-volume/mounts/local-pv4txvc
I1128 14:54:46.788600   38804 reconciler.go:237] Starting operationExecutor.MountVolume for volume "local-pv4txvc" (UniqueName: "kubernetes.io/local-volume/7dfc5864-f2da-11e8-ac39-000c299a5e15-local-pv4txvc") pod "security-context-7dfc4589-f2da-11e8-a0e3-000c299a5e15" (UID: "7dfc5864-f2da-11e8-ac39-000c299a5e15") 
I1128 14:54:46.793714   38804 mount_linux.go:459] Attempting to mount disk: ext4 /dev/loop3 /var/lib/kubelet/plugins/kubernetes.io/local-volume/mounts/local-pv4txvc
I1128 14:54:46.793730   38804 mount_linux.go:146] Mounting cmd (systemd-run) with arguments ([--description=Kubernetes transient mount for /var/lib/kubelet/plugins/kubernetes.io/local-volume/mounts/local-pv4txvc --scope -- mount -t ext4 -o defaults /dev/loop3 /var/lib/kubelet/plugins/kubernetes.io/local-volume/mounts/local-pv4txvc])
Mounting arguments: --description=Kubernetes transient mount for /var/lib/kubelet/plugins/kubernetes.io/local-volume/mounts/local-pv4txvc --scope -- mount -t ext4 -o defaults /dev/loop3 /var/lib/kubelet/plugins/kubernetes.io/local-volume/mounts/local-pv4txvc
I1128 14:54:46.889369   38804 reconciler.go:237] Starting operationExecutor.MountVolume for volume "local-pv4txvc" (UniqueName: "kubernetes.io/local-volume/7dfc5864-f2da-11e8-ac39-000c299a5e15-local-pv4txvc") pod "security-context-7dfc4589-f2da-11e8-a0e3-000c299a5e15" (UID: "7dfc5864-f2da-11e8-ac39-000c299a5e15") 
I1128 14:54:46.989926   38804 reconciler.go:237] Starting operationExecutor.MountVolume for volume "local-pv4txvc" (UniqueName: "kubernetes.io/local-volume/7dfc5864-f2da-11e8-ac39-000c299a5e15-local-pv4txvc") pod "security-context-7dfc4589-f2da-11e8-a0e3-000c299a5e15" (UID: "7dfc5864-f2da-11e8-ac39-000c299a5e15") 
I1128 14:54:47.003670   38804 mount_linux.go:492] Disk successfully formatted (mkfs): ext4 - /dev/loop3 /var/lib/kubelet/plugins/kubernetes.io/local-volume/mounts/local-pv4txvc
I1128 14:54:47.003697   38804 mount_linux.go:146] Mounting cmd (systemd-run) with arguments ([--description=Kubernetes transient mount for /var/lib/kubelet/plugins/kubernetes.io/local-volume/mounts/local-pv4txvc --scope -- mount -t ext4 -o defaults /dev/loop3 /var/lib/kubelet/plugins/kubernetes.io/local-volume/mounts/local-pv4txvc])

# cofyc: kubelet succeeds to mount device for pod 1
I1128 14:54:47.031653   38804 local.go:294] local: successfully mount device /dev/loop3 at /var/lib/kubelet/plugins/kubernetes.io/local-volume/mounts/local-pv4txvc (fstype: ext4)
I1128 14:54:47.031689   38804 operation_generator.go:527] MountVolume.MountDevice succeeded for volume "local-pv4txvc" (UniqueName: "kubernetes.io/local-volume/7dfc5864-f2da-11e8-ac39-000c299a5e15-local-pv4txvc") pod "security-context-7dfc4589-f2da-11e8-a0e3-000c299a5e15" (UID: "7dfc5864-f2da-11e8-ac39-000c299a5e15") device mount path "/var/lib/kubelet/plugins/kubernetes.io/local-volume/mounts/local-pv4txvc"

I1128 14:54:47.031741   38804 local.go:437] LocalVolume mount setup: PodDir(/var/lib/kubelet/pods/7dfc5864-f2da-11e8-ac39-000c299a5e15/volumes/kubernetes.io~local-volume/local-pv4txvc) VolDir(/var/lib/kubelet/plugins/kubernetes.io/local-volume/mounts/local-pv4txvc) Mounted(false) Error(stat /var/lib/kubelet/pods/7dfc5864-f2da-11e8-ac39-000c299a5e15/volumes/kubernetes.io~local-volume/local-pv4txvc: no such file or directory), ReadOnly(false)

I1128 14:54:47.032398   38804 local.go:482] attempting to mount /var/lib/kubelet/pods/7dfc5864-f2da-11e8-ac39-000c299a5e15/volumes/kubernetes.io~local-volume/local-pv4txvc
I1128 14:54:47.032412   38804 mount_linux.go:146] Mounting cmd (systemd-run) with arguments ([--description=Kubernetes transient mount for /var/lib/kubelet/pods/7dfc5864-f2da-11e8-ac39-000c299a5e15/volumes/kubernetes.io~local-volume/local-pv4txvc --scope -- mount -o bind /var/lib/kubelet/plugins/kubernetes.io/local-volume/mounts/local-pv4txvc /var/lib/kubelet/pods/7dfc5864-f2da-11e8-ac39-000c299a5e15/volumes/kubernetes.io~local-volume/local-pv4txvc])
I1128 14:54:47.040879   38804 mount_linux.go:146] Mounting cmd (systemd-run) with arguments ([--description=Kubernetes transient mount for /var/lib/kubelet/pods/7dfc5864-f2da-11e8-ac39-000c299a5e15/volumes/kubernetes.io~local-volume/local-pv4txvc --scope -- mount -o bind,remount /var/lib/kubelet/plugins/kubernetes.io/local-volume/mounts/local-pv4txvc /var/lib/kubelet/pods/7dfc5864-f2da-11e8-ac39-000c299a5e15/volumes/kubernetes.io~local-volume/local-pv4txvc])
I1128 14:54:47.050786   38804 operation_generator.go:567] MountVolume.SetUp succeeded for volume "local-pv4txvc" (UniqueName: "kubernetes.io/local-volume/7dfc5864-f2da-11e8-ac39-000c299a5e15-local-pv4txvc") pod "security-context-7dfc4589-f2da-11e8-a0e3-000c299a5e15" (UID: "7dfc5864-f2da-11e8-ac39-000c299a5e15") 
I1128 14:54:49.997571   38804 request.go:530] Throttling request took 597.502115ms, request: GET:https://localhost:6443/api/v1/persistentvolumes/local-pv4txvc
I1128 14:54:49.999252   38804 desired_state_of_world_populator.go:318] Added volume "volume1" (volSpec="local-pv4txvc") for pod "7dfc5864-f2da-11e8-ac39-000c299a5e15" to desired state.
I1128 14:54:57.197592   38804 request.go:530] Throttling request took 398.303213ms, request: GET:https://localhost:6443/api/v1/persistentvolumes/local-pv4txvc
I1128 14:54:57.200516   38804 desired_state_of_world_populator.go:318] Added volume "volume1" (volSpec="local-pv4txvc") for pod "81c5ae88-f2da-11e8-ac39-000c299a5e15" to desired state.
I1128 14:54:57.207753   38804 desired_state_of_world_populator.go:265] Removing volume from desired state for volume "local-pv4txvc" (UniqueName: "kubernetes.io/local-volume/7dfc5864-f2da-11e8-ac39-000c299a5e15-local-pv4txvc") pod "security-context-7dfc4589-f2da-11e8-a0e3-000c299a5e15" (UID: "7dfc5864-f2da-11e8-ac39-000c299a5e15") 
I1128 14:54:57.272243   38804 reconciler.go:181] operationExecutor.UnmountVolume started for volume "volume1" (UniqueName: "kubernetes.io/local-volume/7dfc5864-f2da-11e8-ac39-000c299a5e15-local-pv4txvc") pod "7dfc5864-f2da-11e8-ac39-000c299a5e15" (UID: "7dfc5864-f2da-11e8-ac39-000c299a5e15") 
I1128 14:54:57.272289   38804 mount_linux.go:874] Cleaning up subpath mounts for /var/lib/kubelet/pods/7dfc5864-f2da-11e8-ac39-000c299a5e15/volume-subpaths/local-pv4txvc
I1128 14:54:57.272346   38804 local.go:544] Unmounting volume "local-pv4txvc" at path "/var/lib/kubelet/pods/7dfc5864-f2da-11e8-ac39-000c299a5e15/volumes/kubernetes.io~local-volume/local-pv4txvc"

I1128 14:54:57.272375   38804 util.go:180] "/var/lib/kubelet/pods/7dfc5864-f2da-11e8-ac39-000c299a5e15/volumes/kubernetes.io~local-volume/local-pv4txvc" is a mountpoint, unmounting

I1128 14:54:57.272381   38804 mount_linux.go:211] Unmounting /var/lib/kubelet/pods/7dfc5864-f2da-11e8-ac39-000c299a5e15/volumes/kubernetes.io~local-volume/local-pv4txvc

I1128 14:54:57.272586   38804 reconciler.go:207] operationExecutor.VerifyControllerAttachedVolume started for volume "local-pv4txvc" (UniqueName: "kubernetes.io/local-volume/81c5ae88-f2da-11e8-ac39-000c299a5e15-local-pv4txvc") pod "security-context-81c59dfe-f2da-11e8-a0e3-000c299a5e15" (UID: "81c5ae88-f2da-11e8-ac39-000c299a5e15") 

I1128 14:54:57.287933   38804 util.go:189] "/var/lib/kubelet/pods/7dfc5864-f2da-11e8-ac39-000c299a5e15/volumes/kubernetes.io~local-volume/local-pv4txvc" is unmounted, deleting the directory

I1128 14:54:57.288038   38804 operation_generator.go:683] UnmountVolume.TearDown succeeded for volume "kubernetes.io/local-volume/7dfc5864-f2da-11e8-ac39-000c299a5e15-local-pv4txvc" (OuterVolumeSpecName: "volume1") pod "7dfc5864-f2da-11e8-ac39-000c299a5e15" (UID: "7dfc5864-f2da-11e8-ac39-000c299a5e15"). InnerVolumeSpecName "local-pv4txvc". PluginName "kubernetes.io/local-volume", VolumeGidValue "777"

I1128 14:54:57.373717   38804 reconciler.go:237] Starting operationExecutor.MountVolume for volume "local-pv4txvc" (UniqueName: "kubernetes.io/local-volume/81c5ae88-f2da-11e8-ac39-000c299a5e15-local-pv4txvc") pod "security-context-81c59dfe-f2da-11e8-a0e3-000c299a5e15" (UID: "81c5ae88-f2da-11e8-ac39-000c299a5e15") 

I1128 14:54:57.373811   38804 reconciler.go:252] operationExecutor.MountVolume started for volume "local-pv4txvc" (UniqueName: "kubernetes.io/local-volume/81c5ae88-f2da-11e8-ac39-000c299a5e15-local-pv4txvc") pod "security-context-81c59dfe-f2da-11e8-a0e3-000c299a5e15" (UID: "81c5ae88-f2da-11e8-ac39-000c299a5e15") 
I1128 14:54:57.373910   38804 reconciler.go:294] operationExecutor.UnmountDevice started for volume "local-pv4txvc" (UniqueName: "kubernetes.io/local-volume/7dfc5864-f2da-11e8-ac39-000c299a5e15-local-pv4txvc") on node "127.0.0.1" 

# cofyc: kubelet mounts device for pod 2
I1128 14:54:57.374151   38804 local.go:260] local: mounting device /dev/loop3 to /var/lib/kubelet/plugins/kubernetes.io/local-volume/mounts/local-pv4txvc

# cofyc: kubelet succeeds to mount device for pod  2
I1128 14:54:57.374205   38804 operation_generator.go:527] MountVolume.MountDevice succeeded for volume "local-pv4txvc" (UniqueName: "kubernetes.io/local-volume/81c5ae88-f2da-11e8-ac39-000c299a5e15-local-pv4txvc") pod "security-context-81c59dfe-f2da-11e8-a0e3-000c299a5e15" (UID: "81c5ae88-f2da-11e8-ac39-000c299a5e15") device mount path "/var/lib/kubelet/plugins/kubernetes.io/local-volume/mounts/local-pv4txvc"

# cofyc mounted: false

I1128 14:54:57.374259   38804 local.go:437] LocalVolume mount setup: PodDir(/var/lib/kubelet/pods/81c5ae88-f2da-11e8-ac39-000c299a5e15/volumes/kubernetes.io~local-volume/local-pv4txvc) VolDir(/var/lib/kubelet/plugins/kubernetes.io/local-volume/mounts/local-pv4txvc) Mounted(false) Error(stat /var/lib/kubelet/pods/81c5ae88-f2da-11e8-ac39-000c299a5e15/volumes/kubernetes.io~local-volume/local-pv4txvc: no such file or directory), ReadOnly(false)

I1128 14:54:57.375217   38804 util.go:180] "/var/lib/kubelet/plugins/kubernetes.io/local-volume/mounts/local-pv4txvc" is a mountpoint, unmounting
I1128 14:54:57.375232   38804 mount_linux.go:211] Unmounting /var/lib/kubelet/plugins/kubernetes.io/local-volume/mounts/local-pv4txvc

# local plugin succeeds to mount volume for Pod 2
I1128 14:54:57.375433   38804 local.go:482] attempting to mount /var/lib/kubelet/pods/81c5ae88-f2da-11e8-ac39-000c299a5e15/volumes/kubernetes.io~local-volume/local-pv4txvc
I1128 14:54:57.375453   38804 mount_linux.go:146] Mounting cmd (systemd-run) with arguments ([--description=Kubernetes transient mount for /var/lib/kubelet/pods/81c5ae88-f2da-11e8-ac39-000c299a5e15/volumes/kubernetes.io~local-volume/local-pv4txvc --scope -- mount -o bind /var/lib/kubelet/plugins/kubernetes.io/local-volume/mounts/local-pv4txvc /var/lib/kubelet/pods/81c5ae88-f2da-11e8-ac39-000c299a5e15/volumes/kubernetes.io~local-volume/local-pv4txvc])
I1128 14:54:57.398641   38804 mount_linux.go:146] Mounting cmd (systemd-run) with arguments ([--description=Kubernetes transient mount for /var/lib/kubelet/pods/81c5ae88-f2da-11e8-ac39-000c299a5e15/volumes/kubernetes.io~local-volume/local-pv4txvc --scope -- mount -o bind,remount /var/lib/kubelet/plugins/kubernetes.io/local-volume/mounts/local-pv4txvc /var/lib/kubelet/pods/81c5ae88-f2da-11e8-ac39-000c299a5e15/volumes/kubernetes.io~local-volume/local-pv4txvc])

# cofyc: but mount source is unmounted and device is unmounted
I1128 14:54:57.407973   38804 util.go:189] "/var/lib/kubelet/plugins/kubernetes.io/local-volume/mounts/local-pv4txvc" is unmounted, deleting the directory
I1128 14:54:57.408016   38804 operation_generator.go:1424] The path isn't device path or doesn't exist. Skip checking device path: 
I1128 14:54:57.408028   38804 operation_generator.go:768] UnmountDevice succeeded for volume "local-pv4txvc" %!(EXTRA string=UnmountDevice succeeded for volume "local-pv4txvc" (UniqueName: "kubernetes.io/local-volume/7dfc5864-f2da-11e8-ac39-000c299a5e15-local-pv4txvc") on node "127.0.0.1" )

# cofyc: failed to mount because "readdirent: no such file or directory"
E1128 14:54:57.418461   38804 nestedpendingoperations.go:267] Operation for "\"kubernetes.io/local-volume/81c5ae88-f2da-11e8-ac39-000c299a5e15-local-pv4txvc\"" failed. No retries permitted until 2018-11-28 14:54:57.918441971 +0800 CST m=+234.084234222 (durationBeforeRetry 500ms). Error: "MountVolume.SetUp failed for volume \"local-pv4txvc\" (UniqueName: \"kubernetes.io/local-volume/81c5ae88-f2da-11e8-ac39-000c299a5e15-local-pv4txvc\") pod \"security-context-81c59dfe-f2da-11e8-a0e3-000c299a5e15\" (UID: \"81c5ae88-f2da-11e8-ac39-000c299a5e15\") : readdirent: no such file or directory"
I1128 14:54:57.418723   38804 server.go:459] Event(v1.ObjectReference{Kind:"Pod", Namespace:"e2e-tests-persistent-local-volumes-test-hdsx8", Name:"security-context-81c59dfe-f2da-11e8-a0e3-000c299a5e15", UID:"81c5ae88-f2da-11e8-ac39-000c299a5e15", APIVersion:"v1", ResourceVersion:"1904", FieldPath:""}): type: 'Warning' reason: 'FailedMount' MountVolume.SetUp failed for volume "local-pv4txvc" : readdirent: no such file or directory

# cofyc: mount again
I1128 14:54:57.474940   38804 reconciler.go:237] Starting operationExecutor.MountVolume for volume "local-pv4txvc" (UniqueName: "kubernetes.io/local-volume/81c5ae88-f2da-11e8-ac39-000c299a5e15-local-pv4txvc") pod "security-context-81c59dfe-f2da-11e8-a0e3-000c299a5e15" (UID: "81c5ae88-f2da-11e8-ac39-000c299a5e15") 

I1128 14:54:57.475133   38804 reconciler.go:301] Volume detached for volume "local-pv4txvc" (UniqueName: "kubernetes.io/local-volume/7dfc5864-f2da-11e8-ac39-000c299a5e15-local-pv4txvc") on node "127.0.0.1" DevicePath ""

I1128 14:54:57.576233   38804 reconciler.go:237] Starting operationExecutor.MountVolume for volume "local-pv4txvc" (UniqueName: "kubernetes.io/local-volume/81c5ae88-f2da-11e8-ac39-000c299a5e15-local-pv4txvc") pod "security-context-81c59dfe-f2da-11e8-a0e3-000c299a5e15" (UID: "81c5ae88-f2da-11e8-ac39-000c299a5e15") 

I1128 14:54:57.677186   38804 reconciler.go:237] Starting operationExecutor.MountVolume for volume "local-pv4txvc" (UniqueName: "kubernetes.io/local-volume/81c5ae88-f2da-11e8-ac39-000c299a5e15-local-pv4txvc") pod "security-context-81c59dfe-f2da-11e8-a0e3-000c299a5e15" (UID: "81c5ae88-f2da-11e8-ac39-000c299a5e15") 
I1128 14:54:57.778212   38804 reconciler.go:237] Starting operationExecutor.MountVolume for volume "local-pv4txvc" (UniqueName: "kubernetes.io/local-volume/81c5ae88-f2da-11e8-ac39-000c299a5e15-local-pv4txvc") pod "security-context-81c59dfe-f2da-11e8-a0e3-000c299a5e15" (UID: "81c5ae88-f2da-11e8-ac39-000c299a5e15") 
I1128 14:54:57.879123   38804 reconciler.go:237] Starting operationExecutor.MountVolume for volume "local-pv4txvc" (UniqueName: "kubernetes.io/local-volume/81c5ae88-f2da-11e8-ac39-000c299a5e15-local-pv4txvc") pod "security-context-81c59dfe-f2da-11e8-a0e3-000c299a5e15" (UID: "81c5ae88-f2da-11e8-ac39-000c299a5e15") 
I1128 14:54:57.979834   38804 reconciler.go:237] Starting operationExecutor.MountVolume for volume "local-pv4txvc" (UniqueName: "kubernetes.io/local-volume/81c5ae88-f2da-11e8-ac39-000c299a5e15-local-pv4txvc") pod "security-context-81c59dfe-f2da-11e8-a0e3-000c299a5e15" (UID: "81c5ae88-f2da-11e8-ac39-000c299a5e15") 
I1128 14:54:57.979966   38804 reconciler.go:252] operationExecutor.MountVolume started for volume "local-pv4txvc" (UniqueName: "kubernetes.io/local-volume/81c5ae88-f2da-11e8-ac39-000c299a5e15-local-pv4txvc") pod "security-context-81c59dfe-f2da-11e8-a0e3-000c299a5e15" (UID: "81c5ae88-f2da-11e8-ac39-000c299a5e15") 

# cofyc: kubelet mounts device to global mount path for pod 2
I1128 14:54:57.980161   38804 local.go:260] local: mounting device /dev/loop3 to /var/lib/kubelet/plugins/kubernetes.io/local-volume/mounts/local-pv4txvc

I1128 14:54:58.032036   38804 mount_linux.go:459] Attempting to mount disk: ext4 /dev/loop3 /var/lib/kubelet/plugins/kubernetes.io/local-volume/mounts/local-pv4txvc
I1128 14:54:58.032066   38804 mount_linux.go:146] Mounting cmd (systemd-run) with arguments ([--description=Kubernetes transient mount for /var/lib/kubelet/plugins/kubernetes.io/local-volume/mounts/local-pv4txvc --scope -- mount -t ext4 -o defaults /dev/loop3 /var/lib/kubelet/plugins/kubernetes.io/local-volume/mounts/local-pv4txvc])

# cofyc: kubelet succeeds to mount device to global mount path for pod 2
I1128 14:54:58.055874   38804 local.go:294] local: successfully mount device /dev/loop3 at /var/lib/kubelet/plugins/kubernetes.io/local-volume/mounts/local-pv4txvc (fstype: ext4)
I1128 14:54:58.055925   38804 operation_generator.go:527] MountVolume.MountDevice succeeded for volume "local-pv4txvc" (UniqueName: "kubernetes.io/local-volume/81c5ae88-f2da-11e8-ac39-000c299a5e15-local-pv4txvc") pod "security-context-81c59dfe-f2da-11e8-a0e3-000c299a5e15" (UID: "81c5ae88-f2da-11e8-ac39-000c299a5e15") device mount path "/var/lib/kubelet/plugins/kubernetes.io/local-volume/mounts/local-pv4txvc"

# cofyc: mounted

I1128 14:54:58.056944   38804 local.go:437] LocalVolume mount setup: PodDir(/var/lib/kubelet/pods/81c5ae88-f2da-11e8-ac39-000c299a5e15/volumes/kubernetes.io~local-volume/local-pv4txvc) VolDir(/var/lib/kubelet/plugins/kubernetes.io/local-volume/mounts/local-pv4txvc) Mounted(true) Error(<nil>), ReadOnly(false)
I1128 14:54:58.057009   38804 operation_generator.go:567] MountVolume.SetUp succeeded for volume "local-pv4txvc" (UniqueName: "kubernetes.io/local-volume/81c5ae88-f2da-11e8-ac39-000c299a5e15-local-pv4txvc") pod "security-context-81c59dfe-f2da-11e8-a0e3-000c299a5e15" (UID: "81c5ae88-f2da-11e8-ac39-000c299a5e15") 

E1128 14:54:59.007202   38804 remote_runtime.go:213] StartContainer "7b1f1d003c638538ffff67b0701310043c2c2328e58b8291b6f10526168ef155" from runtime service failed: rpc error: code = Unknown desc = failed to start container "7b1f1d003c638538ffff67b0701310043c2c2328e58b8291b6f10526168ef155": Error response from daemon: OCI runtime create failed: container_linux.go:348: starting container process caused "process_linux.go:402: container init caused \"rootfs_linux.go:58: mounting \\\"/var/lib/kubelet/pods/81c5ae88-f2da-11e8-ac39-000c299a5e15/volumes/kubernetes.io~local-volume/local-pv4txvc\\\" to rootfs \\\"/data/var/lib/docker/aufs/mnt/17aa5e9dfae41230347c542eb201e1712b5bb1aa77b27c0ff51dd2e2f04d9ed8\\\" at \\\"/data/var/lib/docker/aufs/mnt/17aa5e9dfae41230347c542eb201e1712b5bb1aa77b27c0ff51dd2e2f04d9ed8/mnt/volume1\\\" caused \\\"no such file or directory\\\"\"": unknown

E1128 14:54:59.007257   38804 kuberuntime_manager.go:749] container start failed: RunContainerError: failed to start container "7b1f1d003c638538ffff67b0701310043c2c2328e58b8291b6f10526168ef155": Error response from daemon: OCI runtime create failed: container_linux.go:348: starting container process caused "process_linux.go:402: container init caused \"rootfs_linux.go:58: mounting \\\"/var/lib/kubelet/pods/81c5ae88-f2da-11e8-ac39-000c299a5e15/volumes/kubernetes.io~local-volume/local-pv4txvc\\\" to rootfs \\\"/data/var/lib/docker/aufs/mnt/17aa5e9dfae41230347c542eb201e1712b5bb1aa77b27c0ff51dd2e2f04d9ed8\\\" at \\\"/data/var/lib/docker/aufs/mnt/17aa5e9dfae41230347c542eb201e1712b5bb1aa77b27c0ff51dd2e2f04d9ed8/mnt/volume1\\\" caused \\\"no such file or directory\\\"\"": unknown
E1128 14:54:59.007358   38804 pod_workers.go:190] Error syncing pod 81c5ae88-f2da-11e8-ac39-000c299a5e15 ("security-context-81c59dfe-f2da-11e8-a0e3-000c299a5e15_e2e-tests-persistent-local-volumes-test-hdsx8(81c5ae88-f2da-11e8-ac39-000c299a5e15)"), skipping: failed to "StartContainer" for "write-pod" with RunContainerError: "failed to start container \"7b1f1d003c638538ffff67b0701310043c2c2328e58b8291b6f10526168ef155\": Error response from daemon: OCI runtime create failed: container_linux.go:348: starting container process caused \"process_linux.go:402: container init caused \\\"rootfs_linux.go:58: mounting \\\\\\\"/var/lib/kubelet/pods/81c5ae88-f2da-11e8-ac39-000c299a5e15/volumes/kubernetes.io~local-volume/local-pv4txvc\\\\\\\" to rootfs \\\\\\\"/data/var/lib/docker/aufs/mnt/17aa5e9dfae41230347c542eb201e1712b5bb1aa77b27c0ff51dd2e2f04d9ed8\\\\\\\" at \\\\\\\"/data/var/lib/docker/aufs/mnt/17aa5e9dfae41230347c542eb201e1712b5bb1aa77b27c0ff51dd2e2f04d9ed8/mnt/volume1\\\\\\\" caused \\\\\\\"no such file or directory\\\\\\\"\\\"\": unknown"
I1128 14:54:59.007522   38804 server.go:459] Event(v1.ObjectReference{Kind:"Pod", Namespace:"e2e-tests-persistent-local-volumes-test-hdsx8", Name:"security-context-81c59dfe-f2da-11e8-a0e3-000c299a5e15", UID:"81c5ae88-f2da-11e8-ac39-000c299a5e15", APIVersion:"v1", ResourceVersion:"1904", FieldPath:"spec.containers{write-pod}"}): type: 'Warning' reason: 'Failed' Error: failed to start container "write-pod": Error response from daemon: OCI runtime create failed: container_linux.go:348: starting container process caused "process_linux.go:402: container init caused \"rootfs_linux.go:58: mounting \\\"/var/lib/kubelet/pods/81c5ae88-f2da-11e8-ac39-000c299a5e15/volumes/kubernetes.io~local-volume/local-pv4txvc\\\" to rootfs \\\"/data/var/lib/docker/aufs/mnt/17aa5e9dfae41230347c542eb201e1712b5bb1aa77b27c0ff51dd2e2f04d9ed8\\\" at \\\"/data/var/lib/docker/aufs/mnt/17aa5e9dfae41230347c542eb201e1712b5bb1aa77b27c0ff51dd2e2f04d9ed8/mnt/volume1\\\" caused \\\"no such file or directory\\\"\"": unknown
I1128 14:54:59.597675   38804 request.go:530] Throttling request took 396.900282ms, request: GET:https://localhost:6443/api/v1/persistentvolumes/local-pv4txvc

I1128 14:54:59.600308   38804 desired_state_of_world_populator.go:318] Added volume "volume1" (volSpec="local-pv4txvc") for pod "7dfc5864-f2da-11e8-ac39-000c299a5e15" to desired state.
I1128 14:54:59.694716   38804 reconciler.go:207] operationExecutor.VerifyControllerAttachedVolume started for volume "local-pv4txvc" (UniqueName: "kubernetes.io/local-volume/7dfc5864-f2da-11e8-ac39-000c299a5e15-local-pv4txvc") pod "security-context-7dfc4589-f2da-11e8-a0e3-000c299a5e15" (UID: "7dfc5864-f2da-11e8-ac39-000c299a5e15") 
I1128 14:54:59.795904   38804 reconciler.go:237] Starting operationExecutor.MountVolume for volume "local-pv4txvc" (UniqueName: "kubernetes.io/local-volume/7dfc5864-f2da-11e8-ac39-000c299a5e15-local-pv4txvc") pod "security-context-7dfc4589-f2da-11e8-a0e3-000c299a5e15" (UID: "7dfc5864-f2da-11e8-ac39-000c299a5e15") 
I1128 14:54:59.796093   38804 reconciler.go:252] operationExecutor.MountVolume started for volume "local-pv4txvc" (UniqueName: "kubernetes.io/local-volume/7dfc5864-f2da-11e8-ac39-000c299a5e15-local-pv4txvc") pod "security-context-7dfc4589-f2da-11e8-a0e3-000c299a5e15" (UID: "7dfc5864-f2da-11e8-ac39-000c299a5e15") 

# cofyc: kubelet tries to mount device for pod 1 again
I1128 14:54:59.796327   38804 local.go:260] local: mounting device /dev/loop3 to /var/lib/kubelet/plugins/kubernetes.io/local-volume/mounts/local-pv4txvc
I1128 14:54:59.796383   38804 operation_generator.go:527] MountVolume.MountDevice succeeded for volume "local-pv4txvc" (UniqueName: "kubernetes.io/local-volume/7dfc5864-f2da-11e8-ac39-000c299a5e15-local-pv4txvc") pod "security-context-7dfc4589-f2da-11e8-a0e3-000c299a5e15" (UID: "7dfc5864-f2da-11e8-ac39-000c299a5e15") device mount path "/var/lib/kubelet/plugins/kubernetes.io/local-volume/mounts/local-pv4txvc"

I1128 14:54:59.796434   38804 local.go:437] LocalVolume mount setup: PodDir(/var/lib/kubelet/pods/7dfc5864-f2da-11e8-ac39-000c299a5e15/volumes/kubernetes.io~local-volume/local-pv4txvc) VolDir(/var/lib/kubelet/plugins/kubernetes.io/local-volume/mounts/local-pv4txvc) Mounted(false) Error(stat /var/lib/kubelet/pods/7dfc5864-f2da-11e8-ac39-000c299a5e15/volumes/kubernetes.io~local-volume/local-pv4txvc: no such file or directory), ReadOnly(false)

I1128 14:54:59.797706   38804 local.go:482] attempting to mount /var/lib/kubelet/pods/7dfc5864-f2da-11e8-ac39-000c299a5e15/volumes/kubernetes.io~local-volume/local-pv4txvc
I1128 14:54:59.797726   38804 mount_linux.go:146] Mounting cmd (systemd-run) with arguments ([--description=Kubernetes transient mount for /var/lib/kubelet/pods/7dfc5864-f2da-11e8-ac39-000c299a5e15/volumes/kubernetes.io~local-volume/local-pv4txvc --scope -- mount -o bind /var/lib/kubelet/plugins/kubernetes.io/local-volume/mounts/local-pv4txvc /var/lib/kubelet/pods/7dfc5864-f2da-11e8-ac39-000c299a5e15/volumes/kubernetes.io~local-volume/local-pv4txvc])
I1128 14:54:59.819732   38804 mount_linux.go:146] Mounting cmd (systemd-run) with arguments ([--description=Kubernetes transient mount for /var/lib/kubelet/pods/7dfc5864-f2da-11e8-ac39-000c299a5e15/volumes/kubernetes.io~local-volume/local-pv4txvc --scope -- mount -o bind,remount /var/lib/kubelet/plugins/kubernetes.io/local-volume/mounts/local-pv4txvc /var/lib/kubelet/pods/7dfc5864-f2da-11e8-ac39-000c299a5e15/volumes/kubernetes.io~local-volume/local-pv4txvc])
I1128 14:54:59.839743   38804 operation_generator.go:567] MountVolume.SetUp succeeded for volume "local-pv4txvc" (UniqueName: "kubernetes.io/local-volume/7dfc5864-f2da-11e8-ac39-000c299a5e15-local-pv4txvc") pod "security-context-7dfc4589-f2da-11e8-a0e3-000c299a5e15" (UID: "7dfc5864-f2da-11e8-ac39-000c299a5e15") 


E1128 14:55:00.296548   38804 remote_runtime.go:213] StartContainer "ef678b6034715226672b06c50d55c2dbfd0110244d59ce3b6628c5bbade6c241" from runtime service failed: rpc error: code = Unknown desc = failed to start container "ef678b6034715226672b06c50d55c2dbfd0110244d59ce3b6628c5bbade6c241": Error response from daemon: OCI runtime create failed: container_linux.go:348: starting container process caused "process_linux.go:402: container init caused \"rootfs_linux.go:58: mounting \\\"/var/lib/kubelet/pods/81c5ae88-f2da-11e8-ac39-000c299a5e15/volumes/kubernetes.io~local-volume/local-pv4txvc\\\" to rootfs \\\"/data/var/lib/docker/aufs/mnt/64d511a6df9b28674cf23689b5c62ba1cf0501a41140e2adb4d626aed52de501\\\" at \\\"/data/var/lib/docker/aufs/mnt/64d511a6df9b28674cf23689b5c62ba1cf0501a41140e2adb4d626aed52de501/mnt/volume1\\\" caused \\\"no such file or directory\\\"\"": unknown
E1128 14:55:00.296611   38804 kuberuntime_manager.go:749] container start failed: RunContainerError: failed to start container "ef678b6034715226672b06c50d55c2dbfd0110244d59ce3b6628c5bbade6c241": Error response from daemon: OCI runtime create failed: container_linux.go:348: starting container process caused "process_linux.go:402: container init caused \"rootfs_linux.go:58: mounting \\\"/var/lib/kubelet/pods/81c5ae88-f2da-11e8-ac39-000c299a5e15/volumes/kubernetes.io~local-volume/local-pv4txvc\\\" to rootfs \\\"/data/var/lib/docker/aufs/mnt/64d511a6df9b28674cf23689b5c62ba1cf0501a41140e2adb4d626aed52de501\\\" at \\\"/data/var/lib/docker/aufs/mnt/64d511a6df9b28674cf23689b5c62ba1cf0501a41140e2adb4d626aed52de501/mnt/volume1\\\" caused \\\"no such file or directory\\\"\"": unknown
E1128 14:55:00.296677   38804 pod_workers.go:190] Error syncing pod 81c5ae88-f2da-11e8-ac39-000c299a5e15 ("security-context-81c59dfe-f2da-11e8-a0e3-000c299a5e15_e2e-tests-persistent-local-volumes-test-hdsx8(81c5ae88-f2da-11e8-ac39-000c299a5e15)"), skipping: failed to "StartContainer" for "write-pod" with RunContainerError: "failed to start container \"ef678b6034715226672b06c50d55c2dbfd0110244d59ce3b6628c5bbade6c241\": Error response from daemon: OCI runtime create failed: container_linux.go:348: starting container process caused \"process_linux.go:402: container init caused \\\"rootfs_linux.go:58: mounting \\\\\\\"/var/lib/kubelet/pods/81c5ae88-f2da-11e8-ac39-000c299a5e15/volumes/kubernetes.io~local-volume/local-pv4txvc\\\\\\\" to rootfs \\\\\\\"/data/var/lib/docker/aufs/mnt/64d511a6df9b28674cf23689b5c62ba1cf0501a41140e2adb4d626aed52de501\\\\\\\" at \\\\\\\"/data/var/lib/docker/aufs/mnt/64d511a6df9b28674cf23689b5c62ba1cf0501a41140e2adb4d626aed52de501/mnt/volume1\\\\\\\" caused \\\\\\\"no such file or directory\\\\\\\"\\\"\": unknown"
I1128 14:55:00.296736   38804 server.go:459] Event(v1.ObjectReference{Kind:"Pod", Namespace:"e2e-tests-persistent-local-volumes-test-hdsx8", Name:"security-context-81c59dfe-f2da-11e8-a0e3-000c299a5e15", UID:"81c5ae88-f2da-11e8-ac39-000c299a5e15", APIVersion:"v1", ResourceVersion:"1904", FieldPath:"spec.containers{write-pod}"}): type: 'Warning' reason: 'Failed' Error: failed to start container "write-pod": Error response from daemon: OCI runtime create failed: container_linux.go:348: starting container process caused "process_linux.go:402: container init caused \"rootfs_linux.go:58: mounting \\\"/var/lib/kubelet/pods/81c5ae88-f2da-11e8-ac39-000c299a5e15/volumes/kubernetes.io~local-volume/local-pv4txvc\\\" to rootfs \\\"/data/var/lib/docker/aufs/mnt/64d511a6df9b28674cf23689b5c62ba1cf0501a41140e2adb4d626aed52de501\\\" at \\\"/data/var/lib/docker/aufs/mnt/64d511a6df9b28674cf23689b5c62ba1cf0501a41140e2adb4d626aed52de501/mnt/volume1\\\" caused \\\"no such file or directory\\\"\"": unknown
I1128 14:55:03.998200   38804 request.go:530] Throttling request took 397.66101ms, request: GET:https://localhost:6443/api/v1/persistentvolumes/local-pv4txvc


I1128 14:55:04.000241   38804 desired_state_of_world_populator.go:318] Added volume "volume1" (volSpec="local-pv4txvc") for pod "81c5ae88-f2da-11e8-ac39-000c299a5e15" to desired state.
I1128 14:55:04.007713   38804 desired_state_of_world_populator.go:265] Removing volume from desired state for volume "local-pv4txvc" (UniqueName: "kubernetes.io/local-volume/7dfc5864-f2da-11e8-ac39-000c299a5e15-local-pv4txvc") pod "security-context-7dfc4589-f2da-11e8-a0e3-000c299a5e15" (UID: "7dfc5864-f2da-11e8-ac39-000c299a5e15") 

I1128 14:55:04.036673   38804 reconciler.go:181] operationExecutor.UnmountVolume started for volume "volume1" (UniqueName: "kubernetes.io/local-volume/7dfc5864-f2da-11e8-ac39-000c299a5e15-local-pv4txvc") pod "7dfc5864-f2da-11e8-ac39-000c299a5e15" (UID: "7dfc5864-f2da-11e8-ac39-000c299a5e15") 
I1128 14:55:04.036901   38804 mount_linux.go:874] Cleaning up subpath mounts for /var/lib/kubelet/pods/7dfc5864-f2da-11e8-ac39-000c299a5e15/volume-subpaths/local-pv4txvc
I1128 14:55:04.036978   38804 local.go:544] Unmounting volume "local-pv4txvc" at path "/var/lib/kubelet/pods/7dfc5864-f2da-11e8-ac39-000c299a5e15/volumes/kubernetes.io~local-volume/local-pv4txvc"
I1128 14:55:04.037036   38804 util.go:180] "/var/lib/kubelet/pods/7dfc5864-f2da-11e8-ac39-000c299a5e15/volumes/kubernetes.io~local-volume/local-pv4txvc" is a mountpoint, unmounting
I1128 14:55:04.037051   38804 mount_linux.go:211] Unmounting /var/lib/kubelet/pods/7dfc5864-f2da-11e8-ac39-000c299a5e15/volumes/kubernetes.io~local-volume/local-pv4txvc
I1128 14:55:04.055916   38804 util.go:189] "/var/lib/kubelet/pods/7dfc5864-f2da-11e8-ac39-000c299a5e15/volumes/kubernetes.io~local-volume/local-pv4txvc" is unmounted, deleting the directory
I1128 14:55:04.055984   38804 operation_generator.go:683] UnmountVolume.TearDown succeeded for volume "kubernetes.io/local-volume/7dfc5864-f2da-11e8-ac39-000c299a5e15-local-pv4txvc" (OuterVolumeSpecName: "volume1") pod "7dfc5864-f2da-11e8-ac39-000c299a5e15" (UID: "7dfc5864-f2da-11e8-ac39-000c299a5e15"). InnerVolumeSpecName "local-pv4txvc". PluginName "kubernetes.io/local-volume", VolumeGidValue "777"
I1128 14:55:04.138850   38804 reconciler.go:294] operationExecutor.UnmountDevice started for volume "local-pv4txvc" (UniqueName: "kubernetes.io/local-volume/7dfc5864-f2da-11e8-ac39-000c299a5e15-local-pv4txvc") on node "127.0.0.1" 
I1128 14:55:04.139956   38804 util.go:180] "/var/lib/kubelet/plugins/kubernetes.io/local-volume/mounts/local-pv4txvc" is a mountpoint, unmounting
I1128 14:55:04.139970   38804 mount_linux.go:211] Unmounting /var/lib/kubelet/plugins/kubernetes.io/local-volume/mounts/local-pv4txvc
I1128 14:55:04.176015   38804 util.go:189] "/var/lib/kubelet/plugins/kubernetes.io/local-volume/mounts/local-pv4txvc" is unmounted, deleting the directory
I1128 14:55:04.176136   38804 operation_generator.go:768] UnmountDevice succeeded for volume "local-pv4txvc" %!(EXTRA string=UnmountDevice succeeded for volume "local-pv4txvc" (UniqueName: "kubernetes.io/local-volume/7dfc5864-f2da-11e8-ac39-000c299a5e15-local-pv4txvc") on node "127.0.0.1" )
I1128 14:55:04.239747   38804 reconciler.go:301] Volume detached for volume "local-pv4txvc" (UniqueName: "kubernetes.io/local-volume/7dfc5864-f2da-11e8-ac39-000c299a5e15-local-pv4txvc") on node "127.0.0.1" DevicePath ""
I1128 14:55:07.197412   38804 request.go:530] Throttling request took 397.73341ms, request: GET:https://localhost:6443/api/v1/persistentvolumes/local-pv4txvc
I1128 14:55:07.199153   38804 desired_state_of_world_populator.go:318] Added volume "volume1" (volSpec="local-pv4txvc") for pod "81c5ae88-f2da-11e8-ac39-000c299a5e15" to desired state.
I1128 14:55:09.201801   38804 status_manager.go:499] Patch status for pod "security-context-81c59dfe-f2da-11e8-a0e3-000c299a5e15_e2e-tests-persistent-local-volumes-test-hdsx8(81c5ae88-f2da-11e8-ac39-000c299a5e15)" with "{\"status\":{\"containerStatuses\":[{\"containerID\":\"docker://ef678b6034715226672b06c50d55c2dbfd0110244d59ce3b6628c5bbade6c241\",\"image\":\"busybox:1.29\",\"imageID\":\"docker-pullable://busybox@sha256:2a03a6059f21e150ae84b0973863609494aad70f0a80eaeb64bddd8d92465812\",\"lastState\":{\"terminated\":{\"containerID\":\"docker://ef678b6034715226672b06c50d55c2dbfd0110244d59ce3b6628c5bbade6c241\",\"exitCode\":128,\"finishedAt\":\"2018-11-28T06:55:00Z\",\"message\":\"OCI runtime create failed: container_linux.go:348: starting container process caused \\\"process_linux.go:402: container init caused \\\\\\\"rootfs_linux.go:58: mounting \\\\\\\\\\\\\\\"/var/lib/kubelet/pods/81c5ae88-f2da-11e8-ac39-000c299a5e15/volumes/kubernetes.io~local-volume/local-pv4txvc\\\\\\\\\\\\\\\" to rootfs \\\\\\\\\\\\\\\"/data/var/lib/docker/aufs/mnt/64d511a6df9b28674cf23689b5c62ba1cf0501a41140e2adb4d626aed52de501\\\\\\\\\\\\\\\" at \\\\\\\\\\\\\\\"/data/var/lib/docker/aufs/mnt/64d511a6df9b28674cf23689b5c62ba1cf0501a41140e2adb4d626aed52de501/mnt/volume1\\\\\\\\\\\\\\\" caused \\\\\\\\\\\\\\\"no such file or directory\\\\\\\\\\\\\\\"\\\\\\\"\\\": unknown\",\"reason\":\"ContainerCannotRun\",\"startedAt\":\"2018-11-28T06:55:00Z\"}},\"name\":\"write-pod\",\"ready\":false,\"restartCount\":1,\"state\":{\"waiting\":{\"message\":\"failed to start container \\\"ef678b6034715226672b06c50d55c2dbfd0110244d59ce3b6628c5bbade6c241\\\": Error response from daemon: OCI runtime create failed: container_linux.go:348: starting container process caused \\\"process_linux.go:402: container init caused \\\\\\\"rootfs_linux.go:58: mounting \\\\\\\\\\\\\\\"/var/lib/kubelet/pods/81c5ae88-f2da-11e8-ac39-000c299a5e15/volumes/kubernetes.io~local-volume/local-pv4txvc\\\\\\\\\\\\\\\" to rootfs \\\\\\\\\\\\\\\"/data/var/lib/docker/aufs/mnt/64d511a6df9b28674cf23689b5c62ba1cf0501a41140e2adb4d626aed52de501\\\\\\\\\\\\\\\" at \\\\\\\\\\\\\\\"/data/var/lib/docker/aufs/mnt/64d511a6df9b28674cf23689b5c62ba1cf0501a41140e2adb4d626aed52de501/mnt/volume1\\\\\\\\\\\\\\\" caused \\\\\\\\\\\\\\\"no such file or directory\\\\\\\\\\\\\\\"\\\\\\\"\\\": unknown\",\"reason\":\"RunContainerError\"}}}],\"phase\":\"Running\",\"podIP\":\"172.17.0.7\"}}"

I1128 14:55:09.202013   38804 status_manager.go:506] Status for pod "security-context-81c59dfe-f2da-11e8-a0e3-000c299a5e15_e2e-tests-persistent-local-volumes-test-hdsx8(81c5ae88-f2da-11e8-ac39-000c299a5e15)" updated successfully: (3, {Phase:Running Conditions:[{Type:Initialized Status:True LastProbeTime:0001-01-01 00:00:00 +0000 UTC LastTransitionTime:2018-11-28 14:54:52 +0800 CST Reason: Message:} {Type:Ready Status:False LastProbeTime:0001-01-01 00:00:00 +0000 UTC LastTransitionTime:2018-11-28 14:54:52 +0800 CST Reason:ContainersNotReady Message:containers with unready status: [write-pod]} {Type:ContainersReady Status:False LastProbeTime:0001-01-01 00:00:00 +0000 UTC LastTransitionTime:2018-11-28 14:54:52 +0800 CST Reason:ContainersNotReady Message:containers with unready status: [write-pod]} {Type:PodScheduled Status:True LastProbeTime:0001-01-01 00:00:00 +0000 UTC LastTransitionTime:2018-11-28 14:54:52 +0800 CST Reason: Message:}] Message: Reason: NominatedNodeName: HostIP:127.0.0.1 PodIP:172.17.0.7 StartTime:2018-11-28 14:54:52 +0800 CST InitContainerStatuses:[] ContainerStatuses:[{Name:write-pod State:{Waiting:&ContainerStateWaiting{Reason:RunContainerError,Message:failed to start container "ef678b6034715226672b06c50d55c2dbfd0110244d59ce3b6628c5bbade6c241": Error response from daemon: OCI runtime create failed: container_linux.go:348: starting container process caused "process_linux.go:402: container init caused \"rootfs_linux.go:58: mounting \\\"/var/lib/kubelet/pods/81c5ae88-f2da-11e8-ac39-000c299a5e15/volumes/kubernetes.io~local-volume/local-pv4txvc\\\" to rootfs \\\"/data/var/lib/docker/aufs/mnt/64d511a6df9b28674cf23689b5c62ba1cf0501a41140e2adb4d626aed52de501\\\" at \\\"/data/var/lib/docker/aufs/mnt/64d511a6df9b28674cf23689b5c62ba1cf0501a41140e2adb4d626aed52de501/mnt/volume1\\\" caused \\\"no such file or directory\\\"\"": unknown,} Running:nil Terminated:nil} LastTerminationState:{Waiting:nil Running:nil Terminated:&ContainerStateTerminated{ExitCode:128,Signal:0,Reason:ContainerCannotRun,Message:OCI runtime create failed: container_linux.go:348: starting container process caused "process_linux.go:402: container init caused \"rootfs_linux.go:58: mounting \\\"/var/lib/kubelet/pods/81c5ae88-f2da-11e8-ac39-000c299a5e15/volumes/kubernetes.io~local-volume/local-pv4txvc\\\" to rootfs \\\"/data/var/lib/docker/aufs/mnt/64d511a6df9b28674cf23689b5c62ba1cf0501a41140e2adb4d626aed52de501\\\" at \\\"/data/var/lib/docker/aufs/mnt/64d511a6df9b28674cf23689b5c62ba1cf0501a41140e2adb4d626aed52de501/mnt/volume1\\\" caused \\\"no such file or directory\\\"\"": unknown,StartedAt:2018-11-28 14:55:00 +0800 CST,FinishedAt:2018-11-28 14:55:00 +0800 CST,ContainerID:docker://ef678b6034715226672b06c50d55c2dbfd0110244d59ce3b6628c5bbade6c241,}} Ready:false RestartCount:1 Image:busybox:1.29 ImageID:docker-pullable://busybox@sha256:2a03a6059f21e150ae84b0973863609494aad70f0a80eaeb64bddd8d92465812 ContainerID:docker://ef678b6034715226672b06c50d55c2dbfd0110244d59ce3b6628c5bbade6c241}] QOSClass:BestEffort})

I1128 14:55:18.704608   38804 desired_state_of_world_populator.go:265] Removing volume from desired state for volume "local-pv4txvc" (UniqueName: "kubernetes.io/local-volume/81c5ae88-f2da-11e8-ac39-000c299a5e15-local-pv4txvc") pod "security-context-81c59dfe-f2da-11e8-a0e3-000c299a5e15" (UID: "81c5ae88-f2da-11e8-ac39-000c299a5e15") 
I1128 14:55:18.775589   38804 reconciler.go:181] operationExecutor.UnmountVolume started for volume "volume1" (UniqueName: "kubernetes.io/local-volume/81c5ae88-f2da-11e8-ac39-000c299a5e15-local-pv4txvc") pod "81c5ae88-f2da-11e8-ac39-000c299a5e15" (UID: "81c5ae88-f2da-11e8-ac39-000c299a5e15") 
I1128 14:55:18.775622   38804 mount_linux.go:874] Cleaning up subpath mounts for /var/lib/kubelet/pods/81c5ae88-f2da-11e8-ac39-000c299a5e15/volume-subpaths/local-pv4txvc
I1128 14:55:18.775648   38804 local.go:544] Unmounting volume "local-pv4txvc" at path "/var/lib/kubelet/pods/81c5ae88-f2da-11e8-ac39-000c299a5e15/volumes/kubernetes.io~local-volume/local-pv4txvc"
I1128 14:55:18.776121   38804 util.go:180] "/var/lib/kubelet/pods/81c5ae88-f2da-11e8-ac39-000c299a5e15/volumes/kubernetes.io~local-volume/local-pv4txvc" is a mountpoint, unmounting
I1128 14:55:18.776130   38804 mount_linux.go:211] Unmounting /var/lib/kubelet/pods/81c5ae88-f2da-11e8-ac39-000c299a5e15/volumes/kubernetes.io~local-volume/local-pv4txvc
I1128 14:55:18.797098   38804 util.go:189] "/var/lib/kubelet/pods/81c5ae88-f2da-11e8-ac39-000c299a5e15/volumes/kubernetes.io~local-volume/local-pv4txvc" is unmounted, deleting the directory
I1128 14:55:18.797123   38804 operation_generator.go:683] UnmountVolume.TearDown succeeded for volume "kubernetes.io/local-volume/81c5ae88-f2da-11e8-ac39-000c299a5e15-local-pv4txvc" (OuterVolumeSpecName: "volume1") pod "81c5ae88-f2da-11e8-ac39-000c299a5e15" (UID: "81c5ae88-f2da-11e8-ac39-000c299a5e15"). InnerVolumeSpecName "local-pv4txvc". PluginName "kubernetes.io/local-volume", VolumeGidValue "777"
I1128 14:55:18.876648   38804 reconciler.go:294] operationExecutor.UnmountDevice started for volume "local-pv4txvc" (UniqueName: "kubernetes.io/local-volume/81c5ae88-f2da-11e8-ac39-000c299a5e15-local-pv4txvc") on node "127.0.0.1" 
W1128 14:55:18.876712   38804 util.go:143] Warning: Unmount skipped because path does not exist: /var/lib/kubelet/plugins/kubernetes.io/local-volume/mounts/local-pv4txvc
I1128 14:55:18.876731   38804 operation_generator.go:768] UnmountDevice succeeded for volume "local-pv4txvc" %!(EXTRA string=UnmountDevice succeeded for volume "local-pv4txvc" (UniqueName: "kubernetes.io/local-volume/81c5ae88-f2da-11e8-ac39-000c299a5e15-local-pv4txvc") on node "127.0.0.1" )
I1128 14:55:18.976930   38804 reconciler.go:301] Volume detached for volume "local-pv4txvc" (UniqueName: "kubernetes.io/local-volume/81c5ae88-f2da-11e8-ac39-000c299a5e15-local-pv4txvc") on node "127.0.0.1" DevicePath ""
